{
 "cells": [
  {
   "cell_type": "markdown",
   "id": "a5c4f6c6-6870-4d09-8267-061021bbf351",
   "metadata": {},
   "source": [
    "#### Q1.What is an exception in python ? Write the difference exceptions and syntax error."
   ]
  },
  {
   "cell_type": "markdown",
   "id": "549786ce-2cf5-4697-8d3b-ef181dd1b08d",
   "metadata": {},
   "source": [
    "#### Answer: An exception is an event, which occurs during the execution of a program that disrupts the normal flow of the program's instructions. In general, when a Python script encounters a situation that it cannot cope with, it raises an exception. An exception is a Python object that represents an error.\n",
    "#### Difference exceptions and syntax error:\n",
    "#### Errors cannot be handled, while Python exceptions can be handled at the run time."
   ]
  },
  {
   "cell_type": "markdown",
   "id": "24b4c186-5635-480c-9d39-1fe95df5fd50",
   "metadata": {},
   "source": [
    "#### Q2.What happens when an exception is not handled? Explain with an example."
   ]
  },
  {
   "cell_type": "markdown",
   "id": "8249f1c3-c2d6-4d20-9371-3bee839267f4",
   "metadata": {},
   "source": [
    "#### Answer: If the exception is not handled by an except clause, the exception is re-raised after the finally clause has been executed."
   ]
  },
  {
   "cell_type": "code",
   "execution_count": 3,
   "id": "7cf121fb-2ae0-4799-a505-898571daf042",
   "metadata": {},
   "outputs": [
    {
     "name": "stdout",
     "output_type": "stream",
     "text": [
      "result is 2.0\n",
      "executing finally clause\n",
      "division by zero!\n",
      "executing finally clause\n",
      "executing finally clause\n"
     ]
    },
    {
     "ename": "TypeError",
     "evalue": "unsupported operand type(s) for /: 'str' and 'str'",
     "output_type": "error",
     "traceback": [
      "\u001b[0;31m---------------------------------------------------------------------------\u001b[0m",
      "\u001b[0;31mTypeError\u001b[0m                                 Traceback (most recent call last)",
      "Cell \u001b[0;32mIn[3], line 15\u001b[0m\n\u001b[1;32m     12\u001b[0m divide(\u001b[38;5;241m2\u001b[39m, \u001b[38;5;241m1\u001b[39m)\n\u001b[1;32m     13\u001b[0m divide(\u001b[38;5;241m2\u001b[39m, \u001b[38;5;241m0\u001b[39m)\n\u001b[0;32m---> 15\u001b[0m \u001b[43mdivide\u001b[49m\u001b[43m(\u001b[49m\u001b[38;5;124;43m\"\u001b[39;49m\u001b[38;5;124;43m2\u001b[39;49m\u001b[38;5;124;43m\"\u001b[39;49m\u001b[43m,\u001b[49m\u001b[43m \u001b[49m\u001b[38;5;124;43m\"\u001b[39;49m\u001b[38;5;124;43m1\u001b[39;49m\u001b[38;5;124;43m\"\u001b[39;49m\u001b[43m)\u001b[49m\n",
      "Cell \u001b[0;32mIn[3], line 4\u001b[0m, in \u001b[0;36mdivide\u001b[0;34m(x, y)\u001b[0m\n\u001b[1;32m      2\u001b[0m \u001b[38;5;28;01mdef\u001b[39;00m \u001b[38;5;21mdivide\u001b[39m(x, y):\n\u001b[1;32m      3\u001b[0m     \u001b[38;5;28;01mtry\u001b[39;00m:\n\u001b[0;32m----> 4\u001b[0m         result \u001b[38;5;241m=\u001b[39m \u001b[43mx\u001b[49m\u001b[43m \u001b[49m\u001b[38;5;241;43m/\u001b[39;49m\u001b[43m \u001b[49m\u001b[43my\u001b[49m\n\u001b[1;32m      5\u001b[0m     \u001b[38;5;28;01mexcept\u001b[39;00m \u001b[38;5;167;01mZeroDivisionError\u001b[39;00m:\n\u001b[1;32m      6\u001b[0m         \u001b[38;5;28mprint\u001b[39m(\u001b[38;5;124m\"\u001b[39m\u001b[38;5;124mdivision by zero!\u001b[39m\u001b[38;5;124m\"\u001b[39m)\n",
      "\u001b[0;31mTypeError\u001b[0m: unsupported operand type(s) for /: 'str' and 'str'"
     ]
    }
   ],
   "source": [
    "# example of exception not handled\n",
    "def divide(x, y):\n",
    "    try:\n",
    "        result = x / y\n",
    "    except ZeroDivisionError:\n",
    "        print(\"division by zero!\")\n",
    "    else:\n",
    "        print(\"result is\", result)\n",
    "    finally:\n",
    "        print(\"executing finally clause\")\n",
    "\n",
    "divide(2, 1)\n",
    "divide(2, 0)\n",
    "\n",
    "divide(\"2\", \"1\")"
   ]
  },
  {
   "cell_type": "markdown",
   "id": "41a19423-5c01-4458-88d2-d99e63258ff0",
   "metadata": {},
   "source": [
    "#### Q3.which python statements are used to catch and handle exceptions? Explain with an example."
   ]
  },
  {
   "cell_type": "markdown",
   "id": "b0c7c23e-6bfc-4f17-a1a4-7d6acb8a3523",
   "metadata": {},
   "source": [
    "#### Answer: The try and except block in Python is used to catch and handle exceptions."
   ]
  },
  {
   "cell_type": "code",
   "execution_count": 4,
   "id": "b2365ac6-697c-4c8c-a035-67568f905cbe",
   "metadata": {},
   "outputs": [
    {
     "name": "stdout",
     "output_type": "stream",
     "text": [
      "Variable x is not defined\n"
     ]
    }
   ],
   "source": [
    "#example of try and except\n",
    "try:\n",
    "  print(x)\n",
    "except NameError:\n",
    "  print(\"Variable x is not defined\")\n",
    "except:\n",
    "  print(\"Something else went wrong\")"
   ]
  },
  {
   "cell_type": "markdown",
   "id": "54c1ae96-9048-4932-92df-52315c22b016",
   "metadata": {},
   "source": [
    "#### Q4.explain with an example.\n",
    "#### a. try and else\n",
    "#### b. finally\n",
    "#### c.raise\n"
   ]
  },
  {
   "cell_type": "code",
   "execution_count": 5,
   "id": "a2acfa41-4e9a-42b3-b8b3-bdb20c57f7ec",
   "metadata": {},
   "outputs": [
    {
     "name": "stdout",
     "output_type": "stream",
     "text": [
      "Hello\n",
      "Nothing went wrong\n"
     ]
    }
   ],
   "source": [
    "# a. example of try and else\n",
    "try:\n",
    "  print(\"Hello\")\n",
    "except:\n",
    "  print(\"Something went wrong\")\n",
    "else:\n",
    "  print(\"Nothing went wrong\")"
   ]
  },
  {
   "cell_type": "code",
   "execution_count": 6,
   "id": "e1239769-a20e-456b-ad9a-632faeac73b8",
   "metadata": {},
   "outputs": [
    {
     "name": "stdout",
     "output_type": "stream",
     "text": [
      "Something went wrong\n",
      "The 'try except' is finished\n"
     ]
    }
   ],
   "source": [
    "# b. example of finally\n",
    "try:\n",
    "  print(x)\n",
    "except:\n",
    "  print(\"Something went wrong\")\n",
    "finally:\n",
    "  print(\"The 'try except' is finished\")"
   ]
  },
  {
   "cell_type": "code",
   "execution_count": 7,
   "id": "33192478-5b19-4b97-b0d3-d909f0e0b01c",
   "metadata": {},
   "outputs": [
    {
     "ename": "Exception",
     "evalue": "Sorry, no numbers below zero",
     "output_type": "error",
     "traceback": [
      "\u001b[0;31m---------------------------------------------------------------------------\u001b[0m",
      "\u001b[0;31mException\u001b[0m                                 Traceback (most recent call last)",
      "Cell \u001b[0;32mIn[7], line 5\u001b[0m\n\u001b[1;32m      2\u001b[0m x \u001b[38;5;241m=\u001b[39m \u001b[38;5;241m-\u001b[39m\u001b[38;5;241m1\u001b[39m\n\u001b[1;32m      4\u001b[0m \u001b[38;5;28;01mif\u001b[39;00m x \u001b[38;5;241m<\u001b[39m \u001b[38;5;241m0\u001b[39m:\n\u001b[0;32m----> 5\u001b[0m   \u001b[38;5;28;01mraise\u001b[39;00m \u001b[38;5;167;01mException\u001b[39;00m(\u001b[38;5;124m\"\u001b[39m\u001b[38;5;124mSorry, no numbers below zero\u001b[39m\u001b[38;5;124m\"\u001b[39m)\n",
      "\u001b[0;31mException\u001b[0m: Sorry, no numbers below zero"
     ]
    }
   ],
   "source": [
    "# c. example of raise\n",
    "x = -1\n",
    "\n",
    "if x < 0:\n",
    "  raise Exception(\"Sorry, no numbers below zero\")"
   ]
  },
  {
   "cell_type": "markdown",
   "id": "6fb14141-6485-4d95-8f11-0a8e4fd2034d",
   "metadata": {},
   "source": [
    "#### Q5.what are custom exception in python? why do we need custom exceptions? Explain with an example."
   ]
  },
  {
   "cell_type": "markdown",
   "id": "8a76a4cb-70d8-4bb7-8bda-3c950673fa65",
   "metadata": {},
   "source": [
    "#### Answer: custom exception in python is an Exception object that can include extra data about the cause of the error"
   ]
  },
  {
   "cell_type": "markdown",
   "id": "8315ac42-db5a-4b4d-9ea1-3904218d176c",
   "metadata": {},
   "source": [
    "#### We need custom exception because , Custom exceptions are easy to create, especially when you do not go into all the fuss of adding the .__init__() and .__str__() methods. This is one of these rather rare situations in which less code means more functionality. More often than not, an empty class inheriting from the Exception class is the way to go."
   ]
  },
  {
   "cell_type": "code",
   "execution_count": 13,
   "id": "1cb0997d-a091-4884-8187-1d73211f00f7",
   "metadata": {},
   "outputs": [
    {
     "name": "stdin",
     "output_type": "stream",
     "text": [
      "Enter a number:  0\n"
     ]
    },
    {
     "name": "stdout",
     "output_type": "stream",
     "text": [
      "Input value is zero, try again!\n",
      "\n"
     ]
    }
   ],
   "source": [
    "#example of custom exceptions:\n",
    "#created a class named “Error” derived from the class Exception. \n",
    "#This base class is inherited by various user-defined classes to handle different types of python raise an exception with message\n",
    "class Error(Exception):\n",
    "    \"\"\"Base class for other exceptions\"\"\"\n",
    "    pass\n",
    " \n",
    "class zerodivision(Error):\n",
    "    \"\"\"Raised when the input value is zero\"\"\"\n",
    "    pass\n",
    " \n",
    "try:\n",
    "    i_num = int(input(\"Enter a number: \"))\n",
    "    if i_num == 0:\n",
    "        raise zerodivision\n",
    "except zerodivision:\n",
    "    print(\"Input value is zero, try again!\")\n",
    "    print()"
   ]
  },
  {
   "cell_type": "markdown",
   "id": "70b111c3-e15f-41d2-a10a-490c54e37934",
   "metadata": {},
   "source": [
    "### Q6.create a custom exception class.Use this class to handle exception."
   ]
  },
  {
   "cell_type": "code",
   "execution_count": 14,
   "id": "bb091e83-dacc-4b00-9542-9823b676400e",
   "metadata": {},
   "outputs": [
    {
     "name": "stdout",
     "output_type": "stream",
     "text": [
      "This is my custom exception\n"
     ]
    }
   ],
   "source": [
    "#custom exception class to handle exception\n",
    "class CustomException(Exception):\n",
    "    \"\"\" my custom exception class \"\"\"\n",
    "\n",
    "try:\n",
    "    raise CustomException('This is my custom exception')\n",
    "except CustomException as ex:\n",
    "    print(ex)"
   ]
  },
  {
   "cell_type": "code",
   "execution_count": null,
   "id": "e4681039-9fda-46a1-8cd1-b35121fcde35",
   "metadata": {},
   "outputs": [],
   "source": []
  }
 ],
 "metadata": {
  "kernelspec": {
   "display_name": "Python 3 (ipykernel)",
   "language": "python",
   "name": "python3"
  },
  "language_info": {
   "codemirror_mode": {
    "name": "ipython",
    "version": 3
   },
   "file_extension": ".py",
   "mimetype": "text/x-python",
   "name": "python",
   "nbconvert_exporter": "python",
   "pygments_lexer": "ipython3",
   "version": "3.10.8"
  }
 },
 "nbformat": 4,
 "nbformat_minor": 5
}
